outputs_exec_twap_full/execution_book_public.csv
time,bid,ask,mid,spread,microprice,bid_depth,ask_depth,imbalance,mm_bid_queue,mm_ask_queue
1767225601998,876433,876434,876433,1,876433,1027,1244,-0.0955526,-1,-1
1767225613798,876433,876434,876433,1,876433,372,1180,-0.520619,-1,-1
1767225625797,876376,876377,876376,1,876376,486,1789,-0.572747,-1,-1
1767225637798,876459,876460,876459,1,876460,988,751,0.136285,-1,-1
1767225649797,876459,876460,876459,1,876459,335,1314,-0.593693,-1,-1
1767225661798,876459,876460,876459,1,876459,488,1454,-0.497425,-1,-1
1767225673798,876459,876460,876459,1,876459,903,1223,-0.150517,-1,-1
1767225685998,876459,876460,876459,1,876459,727,1410,-0.319607,-1,-1
1767225698998,876459,876460,876459,1,876459,805,1594,-0.328887,-1,-1
1767225711397,876863,876864,876863,1,876864,1347,520,0.442957,-1,-1
1767225723397,876778,876779,876778,1,876778,509,1864,-0.571007,-1,-1
1767225735398,876738,876739,876738,1,876738,368,1065,-0.486392,-1,-1
1767225747597,876738,876739,876738,1,876739,1366,248,0.692689,-1,-1
1767225759798,876842,876843,876842,1,876843,1285,1028,0.111111,-1,-1
1767225772398,876842,876843,876842,1,876843,1369,590,0.397652,-1,-1
1767225784397,876790,876791,876790,1,876791,865,707,0.100509,-1,-1
1767225796397,876790,876791,876790,1,876791,824,734,0.0577664,-1,-1
1767225808797,876876,876877,876876,1,876877,1223,128,0.810511,-1,-1
1767225820798,876939,876940,876939,1,876940,1293,201,0.730924,-1,-1
1767225832797,877038,877039,877038,1,877038,1219,1226,-0.00286299,-1,-1
1767225844798,876971,876972,876971,1,876971,282,1762,-0.72407,-1,-1
1767225856997,876971,876972,876971,1,876971,279,1495,-0.685457,-1,-1
1767225868998,876971,876972,876971,1,876971,445,1603,-0.56543,-1,-1
1767225880997,876971,876972,876971,1,876972,1175,1054,0.0542844,-1,-1
1767225892997,876971,876972,876971,1,876972,1137,885,0.124629,-1,-1
1767225905397,876971,876972,876971,1,876972,1207,934,0.127511,-1,-1
1767225917398,877415,877416,877415,1,877416,1450,247,0.708898,-1,-1
1767225929397,878027,878028,878027,1,878028,828,721,0.0690768,-1,-1
1767225941398,877604,877605,877604,1,877604,627,2668,-0.619423,-1,-1
1767225953397,877500,877501,877500,1,877500,714,1270,-0.280242,-1,-1
1767225965397,877451,877452,877451,1,877451,677,1630,-0.413091,-1,-1
1767225977997,877428,877429,877428,1,877428,537,1441,-0.457027,-1,-1
1767225989998,877324,877325,877324,1,877324,457,1562,-0.547301,-1,-1
1767226001997,877033,877034,877033,1,877033,401,1571,-0.593306,-1,-1
1767226014397,877107,877108,877107,1,877107,680,1120,-0.244444,-1,-1
1767226026598,877039,877040,877039,1,877040,1205,842,0.177333,-1,-1
1767226038997,877046,877047,877046,1,877047,1440,274,0.68028,-1,-1
1767226051197,877206,877207,877206,1,877206,856,949,-0.0515235,-1,-1
1767226063197,877266,877267,877266,1,877267,1419,222,0.729433,-1,-1
1767226075198,877385,877386,877385,1,877385,749,1158,-0.214473,-1,-1
1767226087197,877385,877386,877385,1,877386,1433,375,0.585177,-1,-1
1767226099197,877385,877386,877385,1,877386,1475,392,0.580075,-1,-1
1767226111398,877385,877386,877385,1,877386,1391,364,0.585185,-1,-1
1767226123597,877673,877674,877673,1,877674,1393,294,0.651452,-1,-1
1767226135598,877553,877554,877553,1,877553,374,1345,-0.564863,-1,-1
1767226147797,877603,877604,877603,1,877604,1005,830,0.0953678,-1,-1
1767226159798,877553,877554,877553,1,877553,574,1432,-0.427717,-1,-1
1767226171798,877573,877574,877573,1,877574,1388,304,0.640662,-1,-1
1767226183798,877573,877574,877573,1,877574,913,759,0.0921053,-1,-1
1767226195797,877652,877653,877652,1,877652,285,1061,-0.576523,-1,-1
1767226207997,877577,877578,877577,1,877578,907,762,0.0868784,-1,-1
1767226219997,877577,877578,877577,1,877577,681,726,-0.0319829,-1,-1
1767226231998,877577,877578,877577,1,877577,288,1093,-0.582911,-1,-1
1767226243998,877521,877522,877521,1,877522,1156,799,0.182609,-1,-1
1767226255998,877521,877522,877521,1,877522,1179,820,0.17959,-1,-1
1767226267997,877521,877522,877521,1,877522,3275,626,0.679057,-1,-1
1767226279998,877467,877468,877467,1,877468,2524,1374,0.295023,-1,-1
1767226292197,877577,877578,877577,1,877577,741,1300,-0.273885,-1,-1
1767226304198,877577,877578,877577,1,877577,1165,1251,-0.035596,-1,-1
1767226316198,877577,877578,877577,1,877577,1029,1275,-0.106771,-1,-1
1767226328397,877577,877578,877577,1,877578,1176,1058,0.0528201,-1,-1
1767226340597,877467,877468,877467,1,877468,2904,642,0.637902,-1,-1
1767226352597,877507,877508,877507,1,877508,3692,719,0.673997,-1,-1
1767226364598,877401,877402,877401,1,877402,1200,1112,0.0380623,-1,-1
1767226376798,877401,877402,877401,1,877402,1338,715,0.303458,-1,-1
1767226388797,877401,877402,877401,1,877401,667,1238,-0.299738,-1,-1
1767226400797,877401,877402,877401,1,877401,669,1134,-0.257903,-1,-1
1767226413398,877401,877402,877401,1,877402,1187,916,0.128864,-1,-1
1767226425598,877401,877402,877401,1,877402,1016,967,0.02471,-1,-1
1767226437597,877390,877391,877390,1,877390,569,1562,-0.465978,-1,-1
1767226449597,877390,877391,877390,1,877390,904,1138,-0.114594,-1,-1
1767226461997,877390,877391,877390,1,877391,1376,742,0.299339,-1,-1
1767226474597,877390,877391,877390,1,877391,1320,981,0.147327,-1,-1
1767226486397,877281,877282,877281,1,877282,1417,651,0.370406,-1,-1
1767226498597,877281,877282,877281,1,877282,1217,329,0.574386,-1,-1
1767226510598,877506,877507,877506,1,877507,1416,664,0.361538,-1,-1
1767226522797,877506,877507,877506,1,877506,876,1141,-0.131383,-1,-1
1767226534997,877560,877561,877560,1,877561,1095,1077,0.00828729,-1,-1
1767226546997,877631,877632,877631,1,877631,540,1529,-0.478009,-1,-1
1767226558997,877599,877600,877599,1,877599,440,1860,-0.617391,-1,-1
1767226570997,877599,877600,877599,1,877599,981,1297,-0.138718,-1,-1
1767226583197,877599,877600,877599,1,877599,759,1488,-0.324433,-1,-1
1767226595198,877599,877600,877599,1,877599,784,1683,-0.36441,-1,-1
1767226607197,877470,877471,877470,1,877470,323,2158,-0.739621,-1,-1
1767226619198,877470,877471,877470,1,877470,387,1533,-0.596875,-1,-1
1767226631197,877426,877427,877426,1,877426,952,1526,-0.231638,-1,-1
1767226643198,877426,877427,877426,1,877427,1237,707,0.272634,-1,-1
1767226655397,877426,877427,877426,1,877427,1279,773,0.246589,-1,-1
1767226667598,877426,877427,877426,1,877427,1199,1031,0.0753363,-1,-1
1767226679597,877426,877427,877426,1,877427,1117,1078,0.0177677,-1,-1
1767226691797,877426,877427,877426,1,877427,1113,1053,0.0277008,-1,-1
1767226703797,877426,877427,877426,1,877427,1228,1187,0.0169772,-1,-1
1767226715798,877426,877427,877426,1,877427,1528,1053,0.184037,-1,-1
1767226728197,877520,877521,877520,1,877521,1534,1073,0.176832,-1,-1
1767226740397,877520,877521,877520,1,877521,1484,614,0.414681,-1,-1
1767226752398,877520,877521,877520,1,877521,1480,344,0.622807,-1,-1
1767226764598,877520,877521,877520,1,877521,1463,342,0.621053,-1,-1
1767226776797,877557,877558,877557,1,877558,1637,480,0.546528,-1,-1
1767226788797,877601,877602,877601,1,877602,1244,487,0.437319,-1,-1
1767226800797,877601,877602,877601,1,877602,1284,333,0.588126,-1,-1
1767226812997,877688,877689,877688,1,877689,741,701,0.0277393,-1,-1
1767226824997,877622,877623,877622,1,877622,397,1362,-0.548607,-1,-1
1767226837998,877622,877623,877622,1,877622,346,1364,-0.595322,-1,-1
1767226849998,877550,877551,877550,1,877550,501,834,-0.249438,-1,-1
1767226862598,877550,877551,877550,1,877551,1414,292,0.657679,-1,-1
1767226874797,877550,877551,877550,1,877551,1317,856,0.212149,-1,-1
1767226887197,877550,877551,877550,1,877551,1385,159,0.794041,-1,-1
1767226899197,877550,877551,877550,1,877551,1419,120,0.844055,-1,-1
1767226911197,877622,877623,877622,1,877622,488,1860,-0.584327,-1,-1
1767226923197,877622,877623,877622,1,877622,627,1696,-0.460181,-1,-1
1767226935197,877622,877623,877622,1,877622,599,1684,-0.475252,-1,-1
1767226947398,877622,877623,877622,1,877622,802,1461,-0.291206,-1,-1
1767226959397,877622,877623,877622,1,877622,909,1257,-0.160665,-1,-1
1767226971398,877622,877623,877622,1,877622,1020,1144,-0.0573013,-1,-1
1767226983397,877725,877726,877725,1,877726,1404,543,0.442219,-1,-1
1767226995397,877725,877726,877725,1,877726,1402,620,0.386746,-1,-1
